Workbook

Sheet INFO
A1: MTMT azonosító:
A2: Név:
A3: Aux:
A4: PhD megszerzésének dátuma (ÉÉÉÉ.HH.NN.):
A5: PhD megszerzésének éve
A6: Közlemények száma:
A7: Tudományos közlemények száma:
A8: Affiliációk:

Sheet OSSZEGZES
A1: https://mta.hu/data/dokumentumok/doktori_tanacs/IX.%20Osztaly/2019/9GJO_DoktoriMinimumkovetelmenyekTara_20190628tol.pdf
A2: (12. oldal)
A3: A pályázó által kitöltendő és a bizottság által ellenőrizendő
A4: Értékelési terület | B4: Szempont | C4: Elért pont-szám | D4: Előírt minimum | E4: Teljesül
A5: 1. Kiemelten értékelt szakkönyv, monográfia írása (legfeljebb 3 db, 112 oldal fölötti könyv az előző fokozat után) | B5: Összesen | C5: ='1_szakkonyv_monog'!C2 -> 0 | D5: 40 | E5: =IF(C5>=D5,"Igen","Nem") -> Nem
A6: 1.1. Ebből idegen nyelven | B6: Összesen | C6: =SUMIF('1_szakkonyv_monog'!H13:H1048576,"<>Magyar",'1_szakkonyv_monog'!R13:R1048576) -> 0 | D6: - | E6: -
A7: 2. Folyóiratban megjelent pontozott közlemények: ezekből: | B7: Összesen | C7: ='2_folyoirat'!C3 -> 0 | D7: 120 | E7: =IF(C7>=D7,"Igen","Nem") -> Nem
B8: PhD óta | C8: =SUMIF('2_folyoirat'!T21:T1048576,"=IGAZ",'2_folyoirat'!U21:U1048576) -> 0 | D8: - | E8: -
A9: 2.1. Nemzetközi listás folyóiratokban | B9: Összesen | C9: =SUMIFS('2_folyoirat'!U21:U1048576,'2_folyoirat'!P21:P1048576,"<>""",'2_folyoirat'!Q21:Q1048576,"=IGAZ") -> 0 | D9: 35 | E9: =IF(C9>=D9,"Igen","Nem") -> Nem
B10: PhD óta | C10: =SUMIFS('2_folyoirat'!U21:U1048576,'2_folyoirat'!P21:P1048576,"<>""",'2_folyoirat'!Q21:Q1048576,"=IGAZ",'2_folyoirat'!T21:T1048576,"=IGAZ") -> 0 | D10: - | E10: -
A11: 2.2. A bizottság nemzetközi listás A vagy B kategóriás folyóirataiban | B11: Összesen | C11: =SUM(SUMIFS('2_folyoirat'!U21:U1048576,'2_folyoirat'!P21:P1048576,"=A",'2_folyoirat'!Q21:Q1048576,"=IGAZ"),SUMIFS('2_folyoirat'!U21:U1048576,'2_folyoirat'!P21:P1048576,"=B",'2_folyoirat'!Q21:Q1048576,"=IGAZ")) -> 0 | D11: - | E11: -
B12: PhD óta | C12: =SUM(SUMIFS('2_folyoirat'!U21:U1048576,'2_folyoirat'!P21:P1048576,"=A",'2_folyoirat'!Q21:Q1048576,"=IGAZ",'2_folyoirat'!T21:T1048576,"=IGAZ"),SUMIFS('2_folyoirat'!U21:U1048576,'2_folyoirat'!P21:P1048576,"=B",'2_folyoirat'!Q21:Q1048576,"=IGAZ",'2_folyoirat'!T21:T1048576,"=IGAZ")) -> 0 | D12: - | E12: -
A13: 2.3. Csak átsorolással (alapesetben nem) pontozott cikkek | B13: Összesen | C13: =SUMIF('2_folyoirat'!P21:P1048576,"",'2_folyoirat'!U21:U1048576) -> 0 | D13: - | E13: -
B14: PhD óta | C14: =SUMIFS('2_folyoirat'!U21:U1048576,'2_folyoirat'!P21:P1048576, "",'2_folyoirat'!T21:T1048576,"IGAZ") -> 0 | D14: - | E14: -
A15: 1-2. összesen | B15: Összesen: | C15: =C5+C7 -> 0 | D15: 180 | E15: =IF(C15>=D15,"Igen","Nem") -> Nem
B16: PhD óta | C16: =SUM(C8,SUMIF('1_szakkonyv_monog'!P13:P17,"=IGAZ",'1_szakkonyv_monog'!R13:R1048576)) -> 0 | D16: - | E16: -
A17: 3. További pontozott közlemények (csak a 3.1-3.4 összegei!) | B17: Összesen | C17: =SUM(C19,C21,C23,C25) -> 0 | D17: - | E17: -
B18: PhD óta | C18: =SUM(C20,C22,C24,C26) -> 0 | D18: - | E18: -
A19: 3.1. További (nem kiemelten értékelt) szakkönyv, monográfia | B19: Összesen | C19: =SUMIF('3_tovabbi'!T23:T1048576,"3.1",'3_tovabbi'!S23:S1048576) -> 0 | D19: - | E19: -
B20: PhD óta | C20: =SUMIFS('3_tovabbi'!S23:S1048576,'3_tovabbi'!Q23:Q1048576,"IGAZ",'3_tovabbi'!T23:T1048576,"3.1") -> 0 | D20: - | E20: -
A21: 3.2 Szakkönyv szerkesztése | B21: Összesen | C21: =SUMIF('3_tovabbi'!T23:T1048576,"3.2",'3_tovabbi'!S23:S1048576) -> 0 | D21: - | E21: -
B22: PhD óta | C22: =SUMIFS('3_tovabbi'!S23:S1048576,'3_tovabbi'!Q23:Q1048576,"IGAZ",'3_tovabbi'!T23:T1048576,"3.2") -> 0 | D22: - | E22: -
A23: 3.3. Tudományos könyvrész | B23: Összesen | C23: =SUMIF('3_tovabbi'!T23:T1048576,"3.3",'3_tovabbi'!S23:S1048576) -> 0 | D23: - | E23: -
B24: PhD óta | C24: =SUMIFS('3_tovabbi'!S23:S1048576,'3_tovabbi'!Q23:Q1048576,"IGAZ",'3_tovabbi'!T23:T1048576,"3.3") -> 0 | D24: - | E24: -
A25: 3.4. Konferenciaközlemény ISBN-es kötetben, ill. ISSN-es folyóiratban | B25: Összesen | C25: =SUMIF('3_tovabbi'!T23:T1048576,"3.4",'3_tovabbi'!S23:S1048576) -> 0 | D25: - | E25: -
B26: PhD óta | C26: =SUMIFS('3_tovabbi'!S23:S1048576,'3_tovabbi'!Q23:Q1048576,"IGAZ",'3_tovabbi'!T23:T1048576,"3.4") -> 0 | D26: - | E26: -
A27: 3.5. További nem pontozott tudományos közlemény | B27: Összesen (db) | C27: {=SUM(IF('3_tovabbi'!T23:T1048576="3.5",1,0))} -> 0 | D27: - | E27: -
B28: PhD óta (db) | C28: {=SUM(IF('3_tovabbi'!T23:T1048576="3.5",1,0))-SUM(IF(('3_tovabbi'!T23:T1048576="3.5")*('3_tovabbi'!Q23:Q1048576=FALSE)*('3_tovabbi'!Q23:Q1048576<>""),1,0))} -> 0 | D28: - | E28: -
A29: 1-2-3. összesen | B29: Összesen | C29: =SUM(C15,C17) -> 0 | D29: - | E29: -
B30: PhD óta | C30: =SUM(C16,C18) -> 0 | D30: - | E30: -
A31: 4. Pontozott hivatkozások (hivatkozott művek / hivatkozások / pontszám) (végig csak pontozott közleményekre!) | B31: 4.1-4.3 összesen | C31: =C34+C37+C43 -> 0 | D31: 80 | E31: =IF(C31>=D31,"Igen","Nem") -> Nem
B32: a PhD óta | C32: =C35+C38+C44 -> 0 | D32: - | E32: -
B33: a PhD utáni közleményekre | C33: =C36+C39+C45 -> 0 | D33: - | E33: -
A34: 4.1. Hivatkozások nemzetközi GJO listás (és átsorolt) folyóiratokban | B34: összesen | C34: =SUM('1_szakkonyv_monog'!W13:W1048576,'2_folyoirat'!Z21:Z1048576,'3_tovabbi'!X23:X1048576) -> 0 | D34: - | E34: -
B35: a PhD óta | C35: =SUM('1_szakkonyv_monog'!AD12:AD1048575,'2_folyoirat'!AG20:AG1048565,'3_tovabbi'!AE22:AE1048567) -> 0 | D35: - | E35: -
B36: a PhD utáni közleményekre | C36: =SUMIF('1_szakkonyv_monog'!P13:P1048576,"IGAZ",'1_szakkonyv_monog'!AD13:AD1048576)+SUMIF('2_folyoirat'!T21:T1048576, "IGAZ",'2_folyoirat'!AG21:AG1048576)+SUMIF('3_tovabbi'!Q23:Q1048576, "IGAZ",'3_tovabbi'!AE23:AE1048576) -> 0 | D36: - | E36: -
A37: 4.2. Hivatkozások nem nemzetközi GJO listás folyóiratokban | B37: összesen | C37: =SUM('1_szakkonyv_monog'!X13:X1048576,'2_folyoirat'!AA21:AA1048576,'3_tovabbi'!Y23:Y1048576) -> 0 | D37: - | E37: -
B38: a PhD óta | C38: =SUM('1_szakkonyv_monog'!AE13:AE1048576,'2_folyoirat'!AH21:AH1048576,'3_tovabbi'!AF23:AF1048576) -> 0 | D38: - | E38: -
B39: a PhD utáni közleményekre | C39: =SUMIF('1_szakkonyv_monog'!P13:P1048576,"IGAZ",'1_szakkonyv_monog'!X13:X1048576)+SUMIF('2_folyoirat'!T21:T1048576, "IGAZ",'2_folyoirat'!AA21:AA1048576)+SUMIF('3_tovabbi'!Q23:Q1048576, "IGAZ",'3_tovabbi'!Y23:Y1048576) -> 0 | D39: - | E39: -
A40: 4.1-4.2 összesen | B40: összesen | C40: =SUM(C34,C37) -> 0 | D40: 40 | E40: =IF(C40>=D40,"Igen","Nem") -> Nem
...

Sheet 1_szakkonyv_monog
A1: ÖSSZEGZÉS | D1: Előírt minimum | E1: Teljesül | G1: "Kiemelten értékelendő könyvek: a jelölt legfeljebb 3 db, önálló vagy legfeljebb egy társszerzővel közösen jegyzett, kandidátusi vagy doktori értekezésétől különböző témájú és tartalmú, korábbi tudományos fokozatának megszerzése után írt teljes Szakkönyve, Monográfiája. Társszerzővel írt könyv akkor javasolható, ha egyértelműen elhatárolt a szerzőség a társszerzők között, és az általa írt rész meghaladja 7 ívet (112 old.). A megjelölt könyvekből a megjelölt (a jelölt által írt) részek együttes terjedelme nem haladhatja meg a 45 ívet (kb. 720 oldalt)." | M1: Információk és teendők: 3 KÖZLEMÉNY KIVÁLASZTÁSA 1. Ezen a lapfülön csak az 1 és 2 szerzős könyvek jelennek meg. A jelöltnek ki kell választania maximum 3 db könyvet, amit ezen az értékelési területen, szakkönyvként vagy monogárfiaként kíván elszámolni. Ezek olyan könyvek, melyek legfeljebb egy társszerzősek, és az összes saját rész maximum 45 ív. 2. A három könyv kiválasztásához a Pontbeszámítás (AG) oszlop értékét kell beállítani a következőre: "Közlemény és hivatkozások után járó pontszám beszámítása". (Alapbeállítás: "Nem kerül beszámításra se a publikációért se a hivatkozás(ok)ért járó pontszám".) 3. Az itt felsorolt, max. 2 szerzős könyvek a 3_tovabbi lapon is megjelennek, így ha szakkönyvként vagy monográfiaként nem kerül elszámolásra a közlemény, akkor további tudományos közleményként (3_tovabbi) el lehet számolni. Figyelni kell, hogy ezeknél a közleményeknél csak az egyik lapfülön legyen a Pontbeszámítás oszlop értéke "Közlemény és hivatkozások után járó pontszám beszámítása" értékű, a másikon "Nem kerül beszámításra se a publikációért se a hivatkozás(ok)ért járó pontszám" legyen az érték. | Z1: Információk és teendők: ÍVSZÁMOK - A szakkönyvek és monográfiák esetében a pontszámítás az ívszám alapján zajlik, ehhez meg kell adni a közlemény össz-ív számát (L). - Egyszerzős könyv esetén a Saját ívek száma megegyezik az össz-ív számmal, mindkét cellát ki kell tölteni. - Többszerzős könyvek esetében, amennyiben elhatárolható, hogy a jelölt hány saját ívet szerzett, azt az értéket a "Saját ívek száma" (Q) oszlopba kell beírni. Ebben az esetben a "Könyv után járó pontszám számolása" (AI) oszlopot "Saját ívek száma alapján" értékre kell állítani. - Többszerzős könyvek esetében, ha nem határolható el a jelölt által írt rész, akkor a pontozott ívszámot a "Szerzők számával normált ívszám" oszlop adja (=össz-ív szám leosztva a szerzők számával). Ebben az esetben a "Könyv után járó pontszám számolása" (AI) oszlopot "Szerzők számával normált ívszám" értékre kell állítani.
A2: 1. Kiemelten értékelt szakkönyv, monográfia írása (legfeljebb 3 db, 112 oldal fölötti könyv az előző fokozat után) | B2: Összesen | C2: =SUM(C7) -> 0 | D2: 40 | E2: =IF(C2>=D2,"Igen","Nem") -> Nem
A5: RÉSZLETEZÉS
A6: Értékelési terület | B6: Szempont | C6: Elért pont-szám | D6: Előírt minimum | E6: Teljesül
A7: 1. Kiemelten értékelt szakkönyv, monográfia írása (legfeljebb 3 db, 112 oldal fölötti könyv az előző fokozat után) | B7: Összesen | C7: =SUM(R13:R1048576) -> 0 | D7: 40 | E7: =IF(C7>=D7,"Igen","Nem") -> Nem
A8: 1.1. Ebből idegen nyelven | B8: Összesen | C8: =SUMIF(H13:H1048576,"<>Magyar",R13:R1048576) -> 0
A11: KÖZLEMÉNYEK ÉS ÉRTÉKELÉSÜK
A12: Közlemény | B12: mtid | C12: Típus | D12: Publikálás éve | E12: Első szerző | F12: Cím | G12: Alcím | H12: Nyelv | I12: Oldalszám | J12: Altípus | K12: Kategória | L12: Össz-ív | M12: Szerzők számával normált ívszám | N12: Norvég lista | O12: Citációk száma | P12: PhD után keletkezett közlemény | Q12: Saját ívek száma | R12: Pontszám | S12: Értékelési terület kódja | T12: Hivatkozás nemzetközi listás folyóiratban (db) | U12: Hivatkozás nem nemzetközi listás folyóiratban (db) | V12: Hivatkozás további teljes tudományos közleményben (db) | W12: Hivatkozás nemzetközi listás folyóiratban (pontszám) | X12: Hivatkozás nem nemzetközi listás folyóiratban (pontszám) | Y12: Hivatkozás további teljes tudományos közleményben (pontszám) | Z12: Citációk száma egyezik-e a hivatkozások számával | AA12: Hivatkozás a phd fokozat megszerzése óta nemzetközi listás folyóiratban (db) | AB12: Hivatkozás a phd fokozat megszerzése óta nem nemzetközi listás folyóiratban (db) | AC12: Hivatkozás a phd fokozat megszerzése óta további teljes tudományos közleményben (db) | AD12: Hivatkozás a phd fokozat megszerzése óta nemzetközi listás folyóiratban (pontszám) | AE12: Hivatkozás a phd fokozat megszerzése óta nem nemzetközi listás folyóiratban (pontszám) | AF12: Hivatkozás a phd fokozat megszerzése óta további teljes tudományos közleményben (pontszám) | AG12: Pontbeszámítás | AH12: Szerzők száma | AI12: Könyv után járó pontszám számolása

Sheet 2_folyoirat
A1: ÖSSZEGZÉS | D1: Előírt minimum | E1: Teljesül | G1: [A pontszám a "Norvég lista", az "Oldalszám", a "Lap értékelés kategória", a "Nemzetközi" és a "Szerzők száma" oszlopok adatai alapján kalkulálódik.]
A3: 2. Folyóiratban megjelent pontozott közlemények: | B3: Összesen | C3: =C9 -> 0 | D3: 120 | E3: =IF(C3>=D3,"Igen","Nem") -> Nem
A4: 1-2. összesen | B4: Összesen | C4: =SUM(C2:C3) -> 0 | D4: 180 | E4: =IF(C4>=D4,"Igen","Nem") -> Nem
A7: RÉSZLETEZÉS
A8: Értékelési terület | B8: Szempont | C8: Elért pont-szám | D8: Előírt minimum | E8: Teljesül
A9: 2. Folyóiratban megjelent pontozott közlemények: ezekből: | B9: Összesen | C9: =SUM(U21:U1048576) -> 0 | D9: 120 | E9: =IF(C9>=D9,"Igen","Nem") -> Nem
B10: PhD óta | C10: =SUMIF(T21:T1048576,"IGAZ",U21:U1048576) -> 0
A11: 2.1. Nemzetközi listás folyóiratokban | B11: Összesen | C11: =SUMIF(Q21:Q1048576,"IGAZ",U21:U1048576) -> 0 | D11: 35 | E11: =IF(C11>=D11,"Igen","Nem") -> Nem
B12: PhD óta | C12: =SUMIFS(U21:U1048576,Q21:Q1048576, "IGAZ",T21:T1048576,"IGAZ") -> 0
A13: 2.2. A bizottság nemzetközi listás A vagy B kategóriás folyóirataiban | B13: Összesen | C13: =SUMIFS(U21:U1048576,P21:P1048576,"A",Q21:Q1048576,"IGAZ") + SUMIFS(U21:U1048576,P21:P1048576,"B",Q21:Q1048576,"IGAZ") -> 0
B14: PhD óta | C14: =SUMIFS(U21:U1048576,P21:P1048576,"A",Q21:Q1048576,"IGAZ",T21:T1048576,"IGAZ") + SUMIFS(U21:U1048576,P21:P1048576,"B",Q21:Q1048576,"IGAZ",T21:T1048576,"IGAZ") -> 0
A15: 2.3. Csak átsorolással (alapesetben nem) pontozott cikkek | B15: Összesen | C15: =SUMIF(P21:P1048576,"",U21:U1048576) -> 0
B16: PhD óta | C16: =SUMIFS(U21:U1048576,P21:P1048576, "",T21:T1048576,"IGAZ") -> 0
A19: KÖZLEMÉNYEK ÉS ÉRTÉKELÉSÜK
A20: Közlemény | B20: mtid | C20: Típus | D20: Publikálás éve | E20: Első szerző | F20: Cím | G20: Alcím | H20: Évfolyam | I20: Szám | J20: Első oldal | K20: Utolsó oldal | L20: Nyelv | M20: Oldalszám | N20: Altípus | O20: Kategória | P20: Lap értékelés kategória | Q20: Nemzetközi | R20: Norvég lista | S20: Citációk száma | T20: PhD után keletkezett közlemény | U20: Pontszám | V20: Értékelési terület kódja | W20: Hivatkozás nemzetközi listás folyóiratban (db) | X20: Hivatkozás nem nemzetközi listás folyóiratban (db) | Y20: Hivatkozás további teljes tudományos közleményben (db) | Z20: Hivatkozás nemzetközi listás folyóiratban (pontszám) | AA20: Hivatkozás nem nemzetközi listás folyóiratban (pontszám) | AB20: Hivatkozás további teljes tudományos közleményben (pontszám) | AC20: Citációk száma egyezik-e a hivatkozások számával | AD20: Hivatkozás a phd fokozat megszerzése óta nemzetközi listás folyóiratban (db) | AE20: Hivatkozás a phd fokozat megszerzése óta nem nemzetközi listás folyóiratban (db) | AF20: Hivatkozás a phd fokozat megszerzése óta további teljes tudományos közleményben (db) | AG20: Hivatkozás a phd fokozat megszerzése óta nemzetközi listás folyóiratban (pontszám) | AH20: Hivatkozás a phd fokozat megszerzése óta nem nemzetközi listás folyóiratban (pontszám) | AI20: Hivatkozás a phd fokozat megszerzése óta további teljes tudományos közleményben (pontszám) | AJ20: Pontbeszámítás | AK20: Szerzők száma

Sheet 3_tovabbi
A1: ÖSSZEGZÉS | G1: [A pontszám az "Értékelési terület kódja", a "Nyelv", az "Oldalszám", a "Saját ívek száma" és a "Szerzők száma" oszlopok adatai alapján kalkulálódik.]
A2: 3. További pontozott közlemények (csak a 3.1-3.4 összegei!) | B2: Összesen | C2: =C7 -> 0
A5: RÉSZLETEZÉS
A6: Értékelési terület | B6: Szempont | C6: Elért pont-szám | D6: Előírt minimum | E6: Teljesül
A7: 3. További pontozott közlemények (csak a 3.1-3.4 összegei!) | B7: Összesen | C7: =SUM(C9,C11,C13,C15) -> 0
B8: PhD óta | C8: =SUM(C10,C12,C14,C16) -> 0
A9: 3.1. További (nem kiemelten értékelt) szakkönyv, monográfia | B9: Összesen | C9: =SUMIF(T23:T1048576,"3.1",S23:S1048576) -> 0
B10: PhD óta | C10: =SUMIFS(S23:S1048576,Q23:Q1048576, "IGAZ",T23:T1048576,"3.1") -> 0
A11: 3.2 Szakkönyv szerkesztése | B11: Összesen | C11: =SUMIF(T23:T1048576,"3.2",S23:S1048576) -> 0
B12: PhD óta | C12: =SUMIFS(S23:S1048576,Q23:Q1048576, "IGAZ",T23:T1048576,"3.2") -> 0
A13: 3.3. Tudományos könyvrész | B13: Összesen | C13: =SUMIF(T23:T1048576,"3.3",S23:S1048576) -> 0
B14: PhD óta | C14: =SUMIFS(S23:S1048576,Q23:Q1048576, "IGAZ",T23:T1048576,"3.3") -> 0
A15: 3.4. Konferenciaközlemény ISBN-es kötetben, ill. ISSN-es folyóiratban | B15: Összesen | C15: =SUMIF(T23:T1048576,"3.4",S23:S1048576) -> 0
B16: PhD óta | C16: =SUMIFS(S23:S1048576,Q23:Q1048576, "IGAZ",T23:T1048576,"3.4") -> 0
A17: 3.5. További nem pontozott tudományos közlemény | B17: Összesen (db) | C17: {=SUM(IF(T23:T1048576="3.5",1,0))} -> 0
B18: PhD óta (db) | C18: {=SUM(IF(T23:T1048576="3.5",1,0))-SUM(IF((Q23:Q1048576=FALSE)*(Q23:Q1048576<>""),1,0))} -> 0
A21: KÖZLEMÉNYEK ÉS ÉRTÉKELÉSÜK
A22: Közlemény | B22: mtid | C22: Típus | D22: Publikálás éve | E22: Első szerző | F22: Cím | G22: Alcím | H22: Nyelv | I22: Oldalszám | J22: Konferencia publikáció | K22: Altípus | L22: Kategória | M22: Lap értékelés kategória | N22: Nemzetközi | O22: Norvég lista | P22: Citációk száma | Q22: PhD után keletkezett közlemény | R22: Saját ívek száma | S22: Pontszám | T22: Értékelési terület kódja | U22: Hivatkozás nemzetközi listás folyóiratban (db) | V22: Hivatkozás nem nemzetközi listás folyóiratban (db) | W22: Hivatkozás további teljes tudományos közleményben (db) | X22: Hivatkozás nemzetközi listás folyóiratban (pontszám) | Y22: Hivatkozás nem nemzetközi listás folyóiratban (pontszám) | Z22: Hivatkozás további teljes tudományos közleményben (pontszám) | AA22: Citációk száma egyezik-e a hivatkozások számával | AB22: Hivatkozás a phd fokozat megszerzése óta nemzetközi listás folyóiratban (db) | AC22: Hivatkozás a phd fokozat megszerzése óta nem nemzetközi listás folyóiratban (db) | AD22: Hivatkozás a phd fokozat megszerzése óta további teljes tudományos közleményben (db) | AE22: Hivatkozás a phd fokozat megszerzése óta nemzetközi listás folyóiratban (pontszám) | AF22: Hivatkozás a phd fokozat megszerzése óta nem nemzetközi listás folyóiratban (pontszám) | AG22: Hivatkozás a phd fokozat megszerzése óta további teljes tudományos közleményben (pontszám) | AH22: Pontbeszámítás | AI22: Szerzők száma

Sheet 4_hivatkozasok
A1: ÖSSZEGZÉS | D1: Előírt minimum | E1: Teljesül | G1: [A hivatkozások lista bővíthető, valamint el is lehet távolítani belőle tételeket. A pontszám a "Típus", a "Lap értékelés kategória", az "Önhivatkozás" és a "Dátum minimum" oszlopok adatai alapján kalkulálódik.]
A2: 4. Pontozott hivatkozások (hivatkozott művek / hivatkozások / pontszám) (végig csak pontozott közleményekre!) | B2: Összesen | C2: =C7 -> 0 | D2: 80 | E2: =IF(C2>=D2,"Igen","Nem") -> Nem
A5: RÉSZLETEZÉS
A6: Értékelési terület | B6: Szempont | C6: Elért pont-szám | D6: Előírt minimum | E6: Teljesül: igen/nem
A7: 4. Pontozott hivatkozások (hivatkozott művek / hivatkozások / pontszám) (végig csak pontozott közleményekre!) | B7: 4.1-4.3 összesen | C7: =SUM(C10,C13,C19) -> 0 | D7: 80 | E7: =IF(C7>=D7,"Igen","Nem") -> Nem
B8: a PhD óta | C8: =C11+C14+C20 -> 0
B9: a PhD utáni közleményekre | C9: =C12+C15+C21 -> 0
A10: 4.1. Hivatkozások nemzetközi GJO listás (és átsorolt) folyóiratokban | B10: összesen | C10: =SUM('1_szakkonyv_monog'!W13:W1048576,'2_folyoirat'!Z21:Z1048576,'3_tovabbi'!X23:X1048576) -> 0
B11: a PhD óta | C11: =SUM('1_szakkonyv_monog'!AD12:AD1048575,'2_folyoirat'!AG20:AG1048565,'3_tovabbi'!AE22:AE1048567) -> 0
B12: a PhD utáni közleményekre | C12: =SUMIF('1_szakkonyv_monog'!P13:P1048576,"IGAZ",'1_szakkonyv_monog'!AD13:AD1048576)+SUMIF('2_folyoirat'!T21:T1048576, "IGAZ",'2_folyoirat'!AG21:AG1048576)+SUMIF('3_tovabbi'!Q23:Q1048576, "IGAZ",'3_tovabbi'!AE23:AE1048576) -> 0
A13: 4.2. Hivatkozások nem nemzetközi GJO listás folyóiratokban | B13: összesen | C13: =SUM('1_szakkonyv_monog'!X13:X1048576,'2_folyoirat'!AA21:AA1048576,'3_tovabbi'!Y23:Y1048576) -> 0
B14: a PhD óta | C14: =SUM('1_szakkonyv_monog'!AE13:AE1048576,'2_folyoirat'!AH21:AH1048576,'3_tovabbi'!AF23:AF1048576) -> 0
B15: a PhD utáni közleményekre | C15: =SUMIF('1_szakkonyv_monog'!P13:P1048576,"IGAZ",'1_szakkonyv_monog'!X13:X1048576)+SUMIF('2_folyoirat'!T21:T1048576, "IGAZ",'2_folyoirat'!AA21:AA1048576)+SUMIF('3_tovabbi'!Q23:Q1048576, "IGAZ",'3_tovabbi'!Y23:Y1048576) -> 0
A16: 4.1-4.2 összesen | B16: összesen | C16: =SUM(C10,C13) -> 0 | D16: 40 | E16: =IF(C16>=D16,"Igen","Nem") -> Nem
B17: a PhD óta | C17: =SUM(C12,C14) -> 0
B18: a PhD utáni közleményekre | C18: =C12+C15 -> 0
A19: 4.3. Hivatkozások további tudományos (ISBN-es és/vagy ISSN-es), nem GJO listás közleményekben | B19: összesen | C19: =SUM('1_szakkonyv_monog'!X13:X1048576,'2_folyoirat'!AB21:AB1048576,'3_tovabbi'!Z23:Z1048576) -> 0
B20: a PhD óta | C20: =SUM('1_szakkonyv_monog'!AF12:AF1048575,'2_folyoirat'!AI20:AI1048565,'3_tovabbi'!AG22:AG1048567) -> 0
B21: a PhD utáni közleményekre | C21: =SUMIF('1_szakkonyv_monog'!P13:P1048576,"IGAZ",'1_szakkonyv_monog'!Y13:Y1048576)+SUMIF('2_folyoirat'!T21:T1048576, "IGAZ",'2_folyoirat'!AB21:AB1048576)+SUMIF('3_tovabbi'!Q23:Q1048576, "IGAZ",'3_tovabbi'!Z23:Z1048576) -> 0
A24: HIVATKOZÁSOK BESOROLÁSA (módosítható)
A25: Közlemény | B25: Közlemény mtid | C25: Közlemény Kategória | D25: mtid | E25: Típus | F25: Lap mtid | G25: Hivatkozás | H25: MTA Besorolás | I25: Norvég lista | J25: Lap értékelése kategória | K25: Független hivatkozások száma | L25: Létrehozás | M25: Publikálás éve | N25: Önhivatkozás | O25: Dátum minimum | P25: PhD fokozat megszerzését követően írt közlemény | Q25: Ér pontot a hivatkozás? | R25: Ér pontot a hivatkozás, mint a fokozat megszerzését követően írt közleményre történt hivatkozás? (Szempont="a PhD utáni közleményekre") | S25: Ér pontot a hivatkozás, mint a fokozat megszerzését követően történt hivatkozás? (Szempont="a PhD óta")
